rango.tests_chapter3.Chapter3LiveServerTests.test_navigate_from_index_to_about
E
======================================================================
ERROR: test_navigate_from_index_to_about (rango.tests_chapter3.Chapter3LiveServerTests)
----------------------------------------------------------------------
Traceback (most recent call last):
  File "C:\Users\2251923o\AppData\Local\conda\conda\envs\rango\lib\site-packages\selenium\webdriver\common\service.py", line 76, in start
    stdin=PIPE)
  File "C:\Users\2251923o\AppData\Local\conda\conda\envs\rango\lib\subprocess.py", line 775, in __init__
    restore_signals, start_new_session)
  File "C:\Users\2251923o\AppData\Local\conda\conda\envs\rango\lib\subprocess.py", line 1178, in _execute_child
    startupinfo)
FileNotFoundError: [WinError 2] The system cannot find the file specified

During handling of the above exception, another exception occurred:

Traceback (most recent call last):
  File "H:\Workspace\tango_with_django_project2\wad2_client_side\wad2\Online\2251923\rango\tests_chapter3.py", line 18, in setUp
    self.browser = webdriver.Chrome(chrome_options=chrome_options,executable_path=r'C:\chromedriver.exe')
  File "C:\Users\2251923o\AppData\Local\conda\conda\envs\rango\lib\site-packages\selenium\webdriver\chrome\webdriver.py", line 73, in __init__
    self.service.start()
  File "C:\Users\2251923o\AppData\Local\conda\conda\envs\rango\lib\site-packages\selenium\webdriver\common\service.py", line 83, in start
    os.path.basename(self.path), self.start_error_message)
selenium.common.exceptions.WebDriverException: Message: 'chromedriver.exe' executable needs to be in PATH. Please see https://sites.google.com/a/chromium.org/chromedriver/home


----------------------------------------------------------------------
Ran 1 test in 0.513s

FAILED (errors=1)
===========================================================================


rango.tests_chapter3.Chapter3LiveServerTests.test_navigate_from_about_to_index
E
======================================================================
ERROR: test_navigate_from_about_to_index (rango.tests_chapter3.Chapter3LiveServerTests)
----------------------------------------------------------------------
Traceback (most recent call last):
  File "C:\Users\2251923o\AppData\Local\conda\conda\envs\rango\lib\site-packages\selenium\webdriver\common\service.py", line 76, in start
    stdin=PIPE)
  File "C:\Users\2251923o\AppData\Local\conda\conda\envs\rango\lib\subprocess.py", line 775, in __init__
    restore_signals, start_new_session)
  File "C:\Users\2251923o\AppData\Local\conda\conda\envs\rango\lib\subprocess.py", line 1178, in _execute_child
    startupinfo)
FileNotFoundError: [WinError 2] The system cannot find the file specified

During handling of the above exception, another exception occurred:

Traceback (most recent call last):
  File "H:\Workspace\tango_with_django_project2\wad2_client_side\wad2\Online\2251923\rango\tests_chapter3.py", line 18, in setUp
    self.browser = webdriver.Chrome(chrome_options=chrome_options,executable_path=r'C:\chromedriver.exe')
  File "C:\Users\2251923o\AppData\Local\conda\conda\envs\rango\lib\site-packages\selenium\webdriver\chrome\webdriver.py", line 73, in __init__
    self.service.start()
  File "C:\Users\2251923o\AppData\Local\conda\conda\envs\rango\lib\site-packages\selenium\webdriver\common\service.py", line 83, in start
    os.path.basename(self.path), self.start_error_message)
selenium.common.exceptions.WebDriverException: Message: 'chromedriver.exe' executable needs to be in PATH. Please see https://sites.google.com/a/chromium.org/chromedriver/home


----------------------------------------------------------------------
Ran 1 test in 0.516s

FAILED (errors=1)
===========================================================================


rango.tests_chapter4.Chapter4ViewTest.test_about_contain_image
F
======================================================================
FAIL: test_about_contain_image (rango.tests_chapter4.Chapter4ViewTest)
----------------------------------------------------------------------
Traceback (most recent call last):
  File "H:\Workspace\tango_with_django_project2\wad2_client_side\wad2\Online\2251923\rango\tests_chapter4.py", line 51, in test_about_contain_image
    self.assertIn('img src="/static/images/', response.content.decode('ascii'))
AssertionError: 'img src="/static/images/' not found in '<!DOCTYPE html>\n\n\n\n<html>\n\t<head>\n\t\t<title>\n\t\t\tRango -\n            \n    \n\n\t\t</title>\n\t</head>\n\t<body>\n\n\t\t<div>\n\t\t\t\n\t\t\t\t<ul>\n\n\t<li><strong>There are no categories present.</strong></li>\n\n</ul>\n\t\t\t\n\t\t</div>\n\n\n\t<div>\n\t\t\t\n\t<h1>About Page</h1>\n\tThis tutorial has been put together by Eve O\'Hagan <br />\n\t<img src="/media/cat.jpg" alt="Picture of a Cat" />\n\t\n\t\t<p>visits: 1</p>\n\n\n\t\t</div>\n\t\t<hr />\n\t\t<div>\n\t\t\t<ul>\n\t\t\t\n\t\t\t\t<li><a href="/rango/login/">Sign In</a></li>\n\t\t\t\t<li><a href="/rango/register/">Sign Up</a></li>\n\t\t\t\n\t\t\t\t<li><a href="/rango/about/">About</a></li>\n\t\t\t\t<li><a href="/rango/">Index</a></li>\n\t\t\t</ul>\n\t\t</div>\n\t</body>\n</html> '

----------------------------------------------------------------------
Ran 1 test in 0.063s

FAILED (failures=1)
===========================================================================


rango.tests_chapter5.Chapter5LiveServerTests.test_population_script
E
======================================================================
ERROR: test_population_script (rango.tests_chapter5.Chapter5LiveServerTests)
----------------------------------------------------------------------
Traceback (most recent call last):
  File "C:\Users\2251923o\AppData\Local\conda\conda\envs\rango\lib\site-packages\selenium\webdriver\common\service.py", line 76, in start
    stdin=PIPE)
  File "C:\Users\2251923o\AppData\Local\conda\conda\envs\rango\lib\subprocess.py", line 775, in __init__
    restore_signals, start_new_session)
  File "C:\Users\2251923o\AppData\Local\conda\conda\envs\rango\lib\subprocess.py", line 1178, in _execute_child
    startupinfo)
FileNotFoundError: [WinError 2] The system cannot find the file specified

During handling of the above exception, another exception occurred:

Traceback (most recent call last):
  File "H:\Workspace\tango_with_django_project2\wad2_client_side\wad2\Online\2251923\rango\tests_chapter5.py", line 26, in setUp
    self.browser = webdriver.Chrome(chrome_options=chrome_options,executable_path=r'C:\chromedriver.exe')
  File "C:\Users\2251923o\AppData\Local\conda\conda\envs\rango\lib\site-packages\selenium\webdriver\chrome\webdriver.py", line 73, in __init__
    self.service.start()
  File "C:\Users\2251923o\AppData\Local\conda\conda\envs\rango\lib\site-packages\selenium\webdriver\common\service.py", line 83, in start
    os.path.basename(self.path), self.start_error_message)
selenium.common.exceptions.WebDriverException: Message: 'chromedriver.exe' executable needs to be in PATH. Please see https://sites.google.com/a/chromium.org/chromedriver/home


----------------------------------------------------------------------
Ran 1 test in 0.524s

FAILED (errors=1)
===========================================================================


rango.tests_chapter5.Chapter5LiveServerTests.test_admin_page_contains_title_url_and_category
E
======================================================================
ERROR: test_admin_page_contains_title_url_and_category (rango.tests_chapter5.Chapter5LiveServerTests)
----------------------------------------------------------------------
Traceback (most recent call last):
  File "C:\Users\2251923o\AppData\Local\conda\conda\envs\rango\lib\site-packages\selenium\webdriver\common\service.py", line 76, in start
    stdin=PIPE)
  File "C:\Users\2251923o\AppData\Local\conda\conda\envs\rango\lib\subprocess.py", line 775, in __init__
    restore_signals, start_new_session)
  File "C:\Users\2251923o\AppData\Local\conda\conda\envs\rango\lib\subprocess.py", line 1178, in _execute_child
    startupinfo)
FileNotFoundError: [WinError 2] The system cannot find the file specified

During handling of the above exception, another exception occurred:

Traceback (most recent call last):
  File "H:\Workspace\tango_with_django_project2\wad2_client_side\wad2\Online\2251923\rango\tests_chapter5.py", line 26, in setUp
    self.browser = webdriver.Chrome(chrome_options=chrome_options,executable_path=r'C:\chromedriver.exe')
  File "C:\Users\2251923o\AppData\Local\conda\conda\envs\rango\lib\site-packages\selenium\webdriver\chrome\webdriver.py", line 73, in __init__
    self.service.start()
  File "C:\Users\2251923o\AppData\Local\conda\conda\envs\rango\lib\site-packages\selenium\webdriver\common\service.py", line 83, in start
    os.path.basename(self.path), self.start_error_message)
selenium.common.exceptions.WebDriverException: Message: 'chromedriver.exe' executable needs to be in PATH. Please see https://sites.google.com/a/chromium.org/chromedriver/home


----------------------------------------------------------------------
Ran 1 test in 0.516s

FAILED (errors=1)
===========================================================================


rango.tests_chapter5.Chapter5LiveServerTests.test_can_create_new_category_via_admin_site
E
======================================================================
ERROR: test_can_create_new_category_via_admin_site (rango.tests_chapter5.Chapter5LiveServerTests)
----------------------------------------------------------------------
Traceback (most recent call last):
  File "C:\Users\2251923o\AppData\Local\conda\conda\envs\rango\lib\site-packages\selenium\webdriver\common\service.py", line 76, in start
    stdin=PIPE)
  File "C:\Users\2251923o\AppData\Local\conda\conda\envs\rango\lib\subprocess.py", line 775, in __init__
    restore_signals, start_new_session)
  File "C:\Users\2251923o\AppData\Local\conda\conda\envs\rango\lib\subprocess.py", line 1178, in _execute_child
    startupinfo)
FileNotFoundError: [WinError 2] The system cannot find the file specified

During handling of the above exception, another exception occurred:

Traceback (most recent call last):
  File "H:\Workspace\tango_with_django_project2\wad2_client_side\wad2\Online\2251923\rango\tests_chapter5.py", line 26, in setUp
    self.browser = webdriver.Chrome(chrome_options=chrome_options,executable_path=r'C:\chromedriver.exe')
  File "C:\Users\2251923o\AppData\Local\conda\conda\envs\rango\lib\site-packages\selenium\webdriver\chrome\webdriver.py", line 73, in __init__
    self.service.start()
  File "C:\Users\2251923o\AppData\Local\conda\conda\envs\rango\lib\site-packages\selenium\webdriver\common\service.py", line 83, in start
    os.path.basename(self.path), self.start_error_message)
selenium.common.exceptions.WebDriverException: Message: 'chromedriver.exe' executable needs to be in PATH. Please see https://sites.google.com/a/chromium.org/chromedriver/home


----------------------------------------------------------------------
Ran 1 test in 0.500s

FAILED (errors=1)
===========================================================================


rango.tests_chapter6.Chapter6LiveServerTests.test_category_redirect_to_desired_page
E
======================================================================
ERROR: test_category_redirect_to_desired_page (rango.tests_chapter6.Chapter6LiveServerTests)
----------------------------------------------------------------------
Traceback (most recent call last):
  File "C:\Users\2251923o\AppData\Local\conda\conda\envs\rango\lib\site-packages\selenium\webdriver\common\service.py", line 76, in start
    stdin=PIPE)
  File "C:\Users\2251923o\AppData\Local\conda\conda\envs\rango\lib\subprocess.py", line 775, in __init__
    restore_signals, start_new_session)
  File "C:\Users\2251923o\AppData\Local\conda\conda\envs\rango\lib\subprocess.py", line 1178, in _execute_child
    startupinfo)
FileNotFoundError: [WinError 2] The system cannot find the file specified

During handling of the above exception, another exception occurred:

Traceback (most recent call last):
  File "H:\Workspace\tango_with_django_project2\wad2_client_side\wad2\Online\2251923\rango\tests_chapter6.py", line 29, in setUp
    self.browser = webdriver.Chrome(chrome_options=chrome_options,executable_path=r'C:\chromedriver.exe')
  File "C:\Users\2251923o\AppData\Local\conda\conda\envs\rango\lib\site-packages\selenium\webdriver\chrome\webdriver.py", line 73, in __init__
    self.service.start()
  File "C:\Users\2251923o\AppData\Local\conda\conda\envs\rango\lib\site-packages\selenium\webdriver\common\service.py", line 83, in start
    os.path.basename(self.path), self.start_error_message)
selenium.common.exceptions.WebDriverException: Message: 'chromedriver.exe' executable needs to be in PATH. Please see https://sites.google.com/a/chromium.org/chromedriver/home


----------------------------------------------------------------------
Ran 1 test in 0.516s

FAILED (errors=1)
===========================================================================


rango.tests_chapter7.Chapter7LiveServerTestCase.test_form_is_saving_new_category
E
======================================================================
ERROR: test_form_is_saving_new_category (rango.tests_chapter7.Chapter7LiveServerTestCase)
----------------------------------------------------------------------
Traceback (most recent call last):
  File "C:\Users\2251923o\AppData\Local\conda\conda\envs\rango\lib\site-packages\selenium\webdriver\common\service.py", line 76, in start
    stdin=PIPE)
  File "C:\Users\2251923o\AppData\Local\conda\conda\envs\rango\lib\subprocess.py", line 775, in __init__
    restore_signals, start_new_session)
  File "C:\Users\2251923o\AppData\Local\conda\conda\envs\rango\lib\subprocess.py", line 1178, in _execute_child
    startupinfo)
FileNotFoundError: [WinError 2] The system cannot find the file specified

During handling of the above exception, another exception occurred:

Traceback (most recent call last):
  File "H:\Workspace\tango_with_django_project2\wad2_client_side\wad2\Online\2251923\rango\tests_chapter7.py", line 33, in setUp
    self.browser = webdriver.Chrome(chrome_options=chrome_options,executable_path=r'C:\chromedriver.exe')
  File "C:\Users\2251923o\AppData\Local\conda\conda\envs\rango\lib\site-packages\selenium\webdriver\chrome\webdriver.py", line 73, in __init__
    self.service.start()
  File "C:\Users\2251923o\AppData\Local\conda\conda\envs\rango\lib\site-packages\selenium\webdriver\common\service.py", line 83, in start
    os.path.basename(self.path), self.start_error_message)
selenium.common.exceptions.WebDriverException: Message: 'chromedriver.exe' executable needs to be in PATH. Please see https://sites.google.com/a/chromium.org/chromedriver/home


----------------------------------------------------------------------
Ran 1 test in 0.523s

FAILED (errors=1)
===========================================================================


rango.tests_chapter7.Chapter7LiveServerTestCase.test_form_error_when_category_field_empty
E
======================================================================
ERROR: test_form_error_when_category_field_empty (rango.tests_chapter7.Chapter7LiveServerTestCase)
----------------------------------------------------------------------
Traceback (most recent call last):
  File "C:\Users\2251923o\AppData\Local\conda\conda\envs\rango\lib\site-packages\selenium\webdriver\common\service.py", line 76, in start
    stdin=PIPE)
  File "C:\Users\2251923o\AppData\Local\conda\conda\envs\rango\lib\subprocess.py", line 775, in __init__
    restore_signals, start_new_session)
  File "C:\Users\2251923o\AppData\Local\conda\conda\envs\rango\lib\subprocess.py", line 1178, in _execute_child
    startupinfo)
FileNotFoundError: [WinError 2] The system cannot find the file specified

During handling of the above exception, another exception occurred:

Traceback (most recent call last):
  File "H:\Workspace\tango_with_django_project2\wad2_client_side\wad2\Online\2251923\rango\tests_chapter7.py", line 33, in setUp
    self.browser = webdriver.Chrome(chrome_options=chrome_options,executable_path=r'C:\chromedriver.exe')
  File "C:\Users\2251923o\AppData\Local\conda\conda\envs\rango\lib\site-packages\selenium\webdriver\chrome\webdriver.py", line 73, in __init__
    self.service.start()
  File "C:\Users\2251923o\AppData\Local\conda\conda\envs\rango\lib\site-packages\selenium\webdriver\common\service.py", line 83, in start
    os.path.basename(self.path), self.start_error_message)
selenium.common.exceptions.WebDriverException: Message: 'chromedriver.exe' executable needs to be in PATH. Please see https://sites.google.com/a/chromium.org/chromedriver/home


----------------------------------------------------------------------
Ran 1 test in 0.517s

FAILED (errors=1)
===========================================================================


rango.tests_chapter7.Chapter7LiveServerTestCase.test_add_category_that_already_exists
E
======================================================================
ERROR: test_add_category_that_already_exists (rango.tests_chapter7.Chapter7LiveServerTestCase)
----------------------------------------------------------------------
Traceback (most recent call last):
  File "C:\Users\2251923o\AppData\Local\conda\conda\envs\rango\lib\site-packages\selenium\webdriver\common\service.py", line 76, in start
    stdin=PIPE)
  File "C:\Users\2251923o\AppData\Local\conda\conda\envs\rango\lib\subprocess.py", line 775, in __init__
    restore_signals, start_new_session)
  File "C:\Users\2251923o\AppData\Local\conda\conda\envs\rango\lib\subprocess.py", line 1178, in _execute_child
    startupinfo)
FileNotFoundError: [WinError 2] The system cannot find the file specified

During handling of the above exception, another exception occurred:

Traceback (most recent call last):
  File "H:\Workspace\tango_with_django_project2\wad2_client_side\wad2\Online\2251923\rango\tests_chapter7.py", line 33, in setUp
    self.browser = webdriver.Chrome(chrome_options=chrome_options,executable_path=r'C:\chromedriver.exe')
  File "C:\Users\2251923o\AppData\Local\conda\conda\envs\rango\lib\site-packages\selenium\webdriver\chrome\webdriver.py", line 73, in __init__
    self.service.start()
  File "C:\Users\2251923o\AppData\Local\conda\conda\envs\rango\lib\site-packages\selenium\webdriver\common\service.py", line 83, in start
    os.path.basename(self.path), self.start_error_message)
selenium.common.exceptions.WebDriverException: Message: 'chromedriver.exe' executable needs to be in PATH. Please see https://sites.google.com/a/chromium.org/chromedriver/home


----------------------------------------------------------------------
Ran 1 test in 0.521s

FAILED (errors=1)
===========================================================================


rango.tests_chapter7.Chapter7LiveServerTestCase.test_form_is_saving_new_page
E
======================================================================
ERROR: test_form_is_saving_new_page (rango.tests_chapter7.Chapter7LiveServerTestCase)
----------------------------------------------------------------------
Traceback (most recent call last):
  File "C:\Users\2251923o\AppData\Local\conda\conda\envs\rango\lib\site-packages\selenium\webdriver\common\service.py", line 76, in start
    stdin=PIPE)
  File "C:\Users\2251923o\AppData\Local\conda\conda\envs\rango\lib\subprocess.py", line 775, in __init__
    restore_signals, start_new_session)
  File "C:\Users\2251923o\AppData\Local\conda\conda\envs\rango\lib\subprocess.py", line 1178, in _execute_child
    startupinfo)
FileNotFoundError: [WinError 2] The system cannot find the file specified

During handling of the above exception, another exception occurred:

Traceback (most recent call last):
  File "H:\Workspace\tango_with_django_project2\wad2_client_side\wad2\Online\2251923\rango\tests_chapter7.py", line 33, in setUp
    self.browser = webdriver.Chrome(chrome_options=chrome_options,executable_path=r'C:\chromedriver.exe')
  File "C:\Users\2251923o\AppData\Local\conda\conda\envs\rango\lib\site-packages\selenium\webdriver\chrome\webdriver.py", line 73, in __init__
    self.service.start()
  File "C:\Users\2251923o\AppData\Local\conda\conda\envs\rango\lib\site-packages\selenium\webdriver\common\service.py", line 83, in start
    os.path.basename(self.path), self.start_error_message)
selenium.common.exceptions.WebDriverException: Message: 'chromedriver.exe' executable needs to be in PATH. Please see https://sites.google.com/a/chromium.org/chromedriver/home


----------------------------------------------------------------------
Ran 1 test in 0.517s

FAILED (errors=1)
===========================================================================


rango.tests_chapter7.Chapter7LiveServerTestCase.test_cleaned_data_from_add_page
E
======================================================================
ERROR: test_cleaned_data_from_add_page (rango.tests_chapter7.Chapter7LiveServerTestCase)
----------------------------------------------------------------------
Traceback (most recent call last):
  File "C:\Users\2251923o\AppData\Local\conda\conda\envs\rango\lib\site-packages\selenium\webdriver\common\service.py", line 76, in start
    stdin=PIPE)
  File "C:\Users\2251923o\AppData\Local\conda\conda\envs\rango\lib\subprocess.py", line 775, in __init__
    restore_signals, start_new_session)
  File "C:\Users\2251923o\AppData\Local\conda\conda\envs\rango\lib\subprocess.py", line 1178, in _execute_child
    startupinfo)
FileNotFoundError: [WinError 2] The system cannot find the file specified

During handling of the above exception, another exception occurred:

Traceback (most recent call last):
  File "H:\Workspace\tango_with_django_project2\wad2_client_side\wad2\Online\2251923\rango\tests_chapter7.py", line 33, in setUp
    self.browser = webdriver.Chrome(chrome_options=chrome_options,executable_path=r'C:\chromedriver.exe')
  File "C:\Users\2251923o\AppData\Local\conda\conda\envs\rango\lib\site-packages\selenium\webdriver\chrome\webdriver.py", line 73, in __init__
    self.service.start()
  File "C:\Users\2251923o\AppData\Local\conda\conda\envs\rango\lib\site-packages\selenium\webdriver\common\service.py", line 83, in start
    os.path.basename(self.path), self.start_error_message)
selenium.common.exceptions.WebDriverException: Message: 'chromedriver.exe' executable needs to be in PATH. Please see https://sites.google.com/a/chromium.org/chromedriver/home


----------------------------------------------------------------------
Ran 1 test in 0.508s

FAILED (errors=1)
===========================================================================


rango.tests_chapter9.Chapter9LiveServerTests.test_register_user
E
======================================================================
ERROR: test_register_user (rango.tests_chapter9.Chapter9LiveServerTests)
----------------------------------------------------------------------
Traceback (most recent call last):
  File "C:\Users\2251923o\AppData\Local\conda\conda\envs\rango\lib\site-packages\selenium\webdriver\common\service.py", line 76, in start
    stdin=PIPE)
  File "C:\Users\2251923o\AppData\Local\conda\conda\envs\rango\lib\subprocess.py", line 775, in __init__
    restore_signals, start_new_session)
  File "C:\Users\2251923o\AppData\Local\conda\conda\envs\rango\lib\subprocess.py", line 1178, in _execute_child
    startupinfo)
FileNotFoundError: [WinError 2] The system cannot find the file specified

During handling of the above exception, another exception occurred:

Traceback (most recent call last):
  File "H:\Workspace\tango_with_django_project2\wad2_client_side\wad2\Online\2251923\rango\tests_chapter9.py", line 47, in setUp
    self.browser = webdriver.Chrome(chrome_options=chrome_options,executable_path=r'C:\chromedriver.exe')
  File "C:\Users\2251923o\AppData\Local\conda\conda\envs\rango\lib\site-packages\selenium\webdriver\chrome\webdriver.py", line 73, in __init__
    self.service.start()
  File "C:\Users\2251923o\AppData\Local\conda\conda\envs\rango\lib\site-packages\selenium\webdriver\common\service.py", line 83, in start
    os.path.basename(self.path), self.start_error_message)
selenium.common.exceptions.WebDriverException: Message: 'chromedriver.exe' executable needs to be in PATH. Please see https://sites.google.com/a/chromium.org/chromedriver/home


----------------------------------------------------------------------
Ran 1 test in 0.501s

FAILED (errors=1)
===========================================================================


rango.tests_chapter9.Chapter9LiveServerTests.test_admin_contains_user_profile
E
======================================================================
ERROR: test_admin_contains_user_profile (rango.tests_chapter9.Chapter9LiveServerTests)
----------------------------------------------------------------------
Traceback (most recent call last):
  File "C:\Users\2251923o\AppData\Local\conda\conda\envs\rango\lib\site-packages\selenium\webdriver\common\service.py", line 76, in start
    stdin=PIPE)
  File "C:\Users\2251923o\AppData\Local\conda\conda\envs\rango\lib\subprocess.py", line 775, in __init__
    restore_signals, start_new_session)
  File "C:\Users\2251923o\AppData\Local\conda\conda\envs\rango\lib\subprocess.py", line 1178, in _execute_child
    startupinfo)
FileNotFoundError: [WinError 2] The system cannot find the file specified

During handling of the above exception, another exception occurred:

Traceback (most recent call last):
  File "H:\Workspace\tango_with_django_project2\wad2_client_side\wad2\Online\2251923\rango\tests_chapter9.py", line 47, in setUp
    self.browser = webdriver.Chrome(chrome_options=chrome_options,executable_path=r'C:\chromedriver.exe')
  File "C:\Users\2251923o\AppData\Local\conda\conda\envs\rango\lib\site-packages\selenium\webdriver\chrome\webdriver.py", line 73, in __init__
    self.service.start()
  File "C:\Users\2251923o\AppData\Local\conda\conda\envs\rango\lib\site-packages\selenium\webdriver\common\service.py", line 83, in start
    os.path.basename(self.path), self.start_error_message)
selenium.common.exceptions.WebDriverException: Message: 'chromedriver.exe' executable needs to be in PATH. Please see https://sites.google.com/a/chromium.org/chromedriver/home


----------------------------------------------------------------------
Ran 1 test in 0.520s

FAILED (errors=1)
===========================================================================


rango.tests_chapter9.Chapter9LiveServerTests.test_links_in_index_page_when_logged
E
======================================================================
ERROR: test_links_in_index_page_when_logged (rango.tests_chapter9.Chapter9LiveServerTests)
----------------------------------------------------------------------
Traceback (most recent call last):
  File "C:\Users\2251923o\AppData\Local\conda\conda\envs\rango\lib\site-packages\selenium\webdriver\common\service.py", line 76, in start
    stdin=PIPE)
  File "C:\Users\2251923o\AppData\Local\conda\conda\envs\rango\lib\subprocess.py", line 775, in __init__
    restore_signals, start_new_session)
  File "C:\Users\2251923o\AppData\Local\conda\conda\envs\rango\lib\subprocess.py", line 1178, in _execute_child
    startupinfo)
FileNotFoundError: [WinError 2] The system cannot find the file specified

During handling of the above exception, another exception occurred:

Traceback (most recent call last):
  File "H:\Workspace\tango_with_django_project2\wad2_client_side\wad2\Online\2251923\rango\tests_chapter9.py", line 47, in setUp
    self.browser = webdriver.Chrome(chrome_options=chrome_options,executable_path=r'C:\chromedriver.exe')
  File "C:\Users\2251923o\AppData\Local\conda\conda\envs\rango\lib\site-packages\selenium\webdriver\chrome\webdriver.py", line 73, in __init__
    self.service.start()
  File "C:\Users\2251923o\AppData\Local\conda\conda\envs\rango\lib\site-packages\selenium\webdriver\common\service.py", line 83, in start
    os.path.basename(self.path), self.start_error_message)
selenium.common.exceptions.WebDriverException: Message: 'chromedriver.exe' executable needs to be in PATH. Please see https://sites.google.com/a/chromium.org/chromedriver/home


----------------------------------------------------------------------
Ran 1 test in 0.516s

FAILED (errors=1)
===========================================================================


rango.tests_chapter9.Chapter9LiveServerTests.test_links_in_index_page_when_not_logged
E
======================================================================
ERROR: test_links_in_index_page_when_not_logged (rango.tests_chapter9.Chapter9LiveServerTests)
----------------------------------------------------------------------
Traceback (most recent call last):
  File "C:\Users\2251923o\AppData\Local\conda\conda\envs\rango\lib\site-packages\selenium\webdriver\common\service.py", line 76, in start
    stdin=PIPE)
  File "C:\Users\2251923o\AppData\Local\conda\conda\envs\rango\lib\subprocess.py", line 775, in __init__
    restore_signals, start_new_session)
  File "C:\Users\2251923o\AppData\Local\conda\conda\envs\rango\lib\subprocess.py", line 1178, in _execute_child
    startupinfo)
FileNotFoundError: [WinError 2] The system cannot find the file specified

During handling of the above exception, another exception occurred:

Traceback (most recent call last):
  File "H:\Workspace\tango_with_django_project2\wad2_client_side\wad2\Online\2251923\rango\tests_chapter9.py", line 47, in setUp
    self.browser = webdriver.Chrome(chrome_options=chrome_options,executable_path=r'C:\chromedriver.exe')
  File "C:\Users\2251923o\AppData\Local\conda\conda\envs\rango\lib\site-packages\selenium\webdriver\chrome\webdriver.py", line 73, in __init__
    self.service.start()
  File "C:\Users\2251923o\AppData\Local\conda\conda\envs\rango\lib\site-packages\selenium\webdriver\common\service.py", line 83, in start
    os.path.basename(self.path), self.start_error_message)
selenium.common.exceptions.WebDriverException: Message: 'chromedriver.exe' executable needs to be in PATH. Please see https://sites.google.com/a/chromium.org/chromedriver/home


----------------------------------------------------------------------
Ran 1 test in 0.500s

FAILED (errors=1)
===========================================================================


rango.tests_chapter9.Chapter9LiveServerTests.test_logout_link
E
======================================================================
ERROR: test_logout_link (rango.tests_chapter9.Chapter9LiveServerTests)
----------------------------------------------------------------------
Traceback (most recent call last):
  File "C:\Users\2251923o\AppData\Local\conda\conda\envs\rango\lib\site-packages\selenium\webdriver\common\service.py", line 76, in start
    stdin=PIPE)
  File "C:\Users\2251923o\AppData\Local\conda\conda\envs\rango\lib\subprocess.py", line 775, in __init__
    restore_signals, start_new_session)
  File "C:\Users\2251923o\AppData\Local\conda\conda\envs\rango\lib\subprocess.py", line 1178, in _execute_child
    startupinfo)
FileNotFoundError: [WinError 2] The system cannot find the file specified

During handling of the above exception, another exception occurred:

Traceback (most recent call last):
  File "H:\Workspace\tango_with_django_project2\wad2_client_side\wad2\Online\2251923\rango\tests_chapter9.py", line 47, in setUp
    self.browser = webdriver.Chrome(chrome_options=chrome_options,executable_path=r'C:\chromedriver.exe')
  File "C:\Users\2251923o\AppData\Local\conda\conda\envs\rango\lib\site-packages\selenium\webdriver\chrome\webdriver.py", line 73, in __init__
    self.service.start()
  File "C:\Users\2251923o\AppData\Local\conda\conda\envs\rango\lib\site-packages\selenium\webdriver\common\service.py", line 83, in start
    os.path.basename(self.path), self.start_error_message)
selenium.common.exceptions.WebDriverException: Message: 'chromedriver.exe' executable needs to be in PATH. Please see https://sites.google.com/a/chromium.org/chromedriver/home


----------------------------------------------------------------------
Ran 1 test in 0.504s

FAILED (errors=1)
===========================================================================


rango.tests_chapter9.Chapter9LiveServerTests.test_add_category_when_logged
E
======================================================================
ERROR: test_add_category_when_logged (rango.tests_chapter9.Chapter9LiveServerTests)
----------------------------------------------------------------------
Traceback (most recent call last):
  File "C:\Users\2251923o\AppData\Local\conda\conda\envs\rango\lib\site-packages\selenium\webdriver\common\service.py", line 76, in start
    stdin=PIPE)
  File "C:\Users\2251923o\AppData\Local\conda\conda\envs\rango\lib\subprocess.py", line 775, in __init__
    restore_signals, start_new_session)
  File "C:\Users\2251923o\AppData\Local\conda\conda\envs\rango\lib\subprocess.py", line 1178, in _execute_child
    startupinfo)
FileNotFoundError: [WinError 2] The system cannot find the file specified

During handling of the above exception, another exception occurred:

Traceback (most recent call last):
  File "H:\Workspace\tango_with_django_project2\wad2_client_side\wad2\Online\2251923\rango\tests_chapter9.py", line 47, in setUp
    self.browser = webdriver.Chrome(chrome_options=chrome_options,executable_path=r'C:\chromedriver.exe')
  File "C:\Users\2251923o\AppData\Local\conda\conda\envs\rango\lib\site-packages\selenium\webdriver\chrome\webdriver.py", line 73, in __init__
    self.service.start()
  File "C:\Users\2251923o\AppData\Local\conda\conda\envs\rango\lib\site-packages\selenium\webdriver\common\service.py", line 83, in start
    os.path.basename(self.path), self.start_error_message)
selenium.common.exceptions.WebDriverException: Message: 'chromedriver.exe' executable needs to be in PATH. Please see https://sites.google.com/a/chromium.org/chromedriver/home


----------------------------------------------------------------------
Ran 1 test in 0.515s

FAILED (errors=1)
===========================================================================


rango.tests_chapter9.Chapter9LiveServerTests.test_add_page_when_logged
E
======================================================================
ERROR: test_add_page_when_logged (rango.tests_chapter9.Chapter9LiveServerTests)
----------------------------------------------------------------------
Traceback (most recent call last):
  File "C:\Users\2251923o\AppData\Local\conda\conda\envs\rango\lib\site-packages\selenium\webdriver\common\service.py", line 76, in start
    stdin=PIPE)
  File "C:\Users\2251923o\AppData\Local\conda\conda\envs\rango\lib\subprocess.py", line 775, in __init__
    restore_signals, start_new_session)
  File "C:\Users\2251923o\AppData\Local\conda\conda\envs\rango\lib\subprocess.py", line 1178, in _execute_child
    startupinfo)
FileNotFoundError: [WinError 2] The system cannot find the file specified

During handling of the above exception, another exception occurred:

Traceback (most recent call last):
  File "H:\Workspace\tango_with_django_project2\wad2_client_side\wad2\Online\2251923\rango\tests_chapter9.py", line 47, in setUp
    self.browser = webdriver.Chrome(chrome_options=chrome_options,executable_path=r'C:\chromedriver.exe')
  File "C:\Users\2251923o\AppData\Local\conda\conda\envs\rango\lib\site-packages\selenium\webdriver\chrome\webdriver.py", line 73, in __init__
    self.service.start()
  File "C:\Users\2251923o\AppData\Local\conda\conda\envs\rango\lib\site-packages\selenium\webdriver\common\service.py", line 83, in start
    os.path.basename(self.path), self.start_error_message)
selenium.common.exceptions.WebDriverException: Message: 'chromedriver.exe' executable needs to be in PATH. Please see https://sites.google.com/a/chromium.org/chromedriver/home


----------------------------------------------------------------------
Ran 1 test in 0.521s

FAILED (errors=1)
===========================================================================


rango.tests_chapter9.Chapter9LiveServerTests.test_add_page_when_not_logged
E
======================================================================
ERROR: test_add_page_when_not_logged (rango.tests_chapter9.Chapter9LiveServerTests)
----------------------------------------------------------------------
Traceback (most recent call last):
  File "C:\Users\2251923o\AppData\Local\conda\conda\envs\rango\lib\site-packages\selenium\webdriver\common\service.py", line 76, in start
    stdin=PIPE)
  File "C:\Users\2251923o\AppData\Local\conda\conda\envs\rango\lib\subprocess.py", line 775, in __init__
    restore_signals, start_new_session)
  File "C:\Users\2251923o\AppData\Local\conda\conda\envs\rango\lib\subprocess.py", line 1178, in _execute_child
    startupinfo)
FileNotFoundError: [WinError 2] The system cannot find the file specified

During handling of the above exception, another exception occurred:

Traceback (most recent call last):
  File "H:\Workspace\tango_with_django_project2\wad2_client_side\wad2\Online\2251923\rango\tests_chapter9.py", line 47, in setUp
    self.browser = webdriver.Chrome(chrome_options=chrome_options,executable_path=r'C:\chromedriver.exe')
  File "C:\Users\2251923o\AppData\Local\conda\conda\envs\rango\lib\site-packages\selenium\webdriver\chrome\webdriver.py", line 73, in __init__
    self.service.start()
  File "C:\Users\2251923o\AppData\Local\conda\conda\envs\rango\lib\site-packages\selenium\webdriver\common\service.py", line 83, in start
    os.path.basename(self.path), self.start_error_message)
selenium.common.exceptions.WebDriverException: Message: 'chromedriver.exe' executable needs to be in PATH. Please see https://sites.google.com/a/chromium.org/chromedriver/home


----------------------------------------------------------------------
Ran 1 test in 0.503s

FAILED (errors=1)
===========================================================================


rango.tests_chapter9.Chapter9LiveServerTests.test_access_restricted_page_when_logged
E
======================================================================
ERROR: test_access_restricted_page_when_logged (rango.tests_chapter9.Chapter9LiveServerTests)
----------------------------------------------------------------------
Traceback (most recent call last):
  File "C:\Users\2251923o\AppData\Local\conda\conda\envs\rango\lib\site-packages\selenium\webdriver\common\service.py", line 76, in start
    stdin=PIPE)
  File "C:\Users\2251923o\AppData\Local\conda\conda\envs\rango\lib\subprocess.py", line 775, in __init__
    restore_signals, start_new_session)
  File "C:\Users\2251923o\AppData\Local\conda\conda\envs\rango\lib\subprocess.py", line 1178, in _execute_child
    startupinfo)
FileNotFoundError: [WinError 2] The system cannot find the file specified

During handling of the above exception, another exception occurred:

Traceback (most recent call last):
  File "H:\Workspace\tango_with_django_project2\wad2_client_side\wad2\Online\2251923\rango\tests_chapter9.py", line 47, in setUp
    self.browser = webdriver.Chrome(chrome_options=chrome_options,executable_path=r'C:\chromedriver.exe')
  File "C:\Users\2251923o\AppData\Local\conda\conda\envs\rango\lib\site-packages\selenium\webdriver\chrome\webdriver.py", line 73, in __init__
    self.service.start()
  File "C:\Users\2251923o\AppData\Local\conda\conda\envs\rango\lib\site-packages\selenium\webdriver\common\service.py", line 83, in start
    os.path.basename(self.path), self.start_error_message)
selenium.common.exceptions.WebDriverException: Message: 'chromedriver.exe' executable needs to be in PATH. Please see https://sites.google.com/a/chromium.org/chromedriver/home


----------------------------------------------------------------------
Ran 1 test in 0.516s

FAILED (errors=1)
===========================================================================


rango.tests_chapter9.Chapter9LiveServerTests.test_access_restricted_page_when_not_logged
E
======================================================================
ERROR: test_access_restricted_page_when_not_logged (rango.tests_chapter9.Chapter9LiveServerTests)
----------------------------------------------------------------------
Traceback (most recent call last):
  File "C:\Users\2251923o\AppData\Local\conda\conda\envs\rango\lib\site-packages\selenium\webdriver\common\service.py", line 76, in start
    stdin=PIPE)
  File "C:\Users\2251923o\AppData\Local\conda\conda\envs\rango\lib\subprocess.py", line 775, in __init__
    restore_signals, start_new_session)
  File "C:\Users\2251923o\AppData\Local\conda\conda\envs\rango\lib\subprocess.py", line 1178, in _execute_child
    startupinfo)
FileNotFoundError: [WinError 2] The system cannot find the file specified

During handling of the above exception, another exception occurred:

Traceback (most recent call last):
  File "H:\Workspace\tango_with_django_project2\wad2_client_side\wad2\Online\2251923\rango\tests_chapter9.py", line 47, in setUp
    self.browser = webdriver.Chrome(chrome_options=chrome_options,executable_path=r'C:\chromedriver.exe')
  File "C:\Users\2251923o\AppData\Local\conda\conda\envs\rango\lib\site-packages\selenium\webdriver\chrome\webdriver.py", line 73, in __init__
    self.service.start()
  File "C:\Users\2251923o\AppData\Local\conda\conda\envs\rango\lib\site-packages\selenium\webdriver\common\service.py", line 83, in start
    os.path.basename(self.path), self.start_error_message)
selenium.common.exceptions.WebDriverException: Message: 'chromedriver.exe' executable needs to be in PATH. Please see https://sites.google.com/a/chromium.org/chromedriver/home


----------------------------------------------------------------------
Ran 1 test in 0.518s

FAILED (errors=1)
===========================================================================


rango.tests_chapter9.Chapter9LiveServerTests.test_logged_user_message_in_index
E
======================================================================
ERROR: test_logged_user_message_in_index (rango.tests_chapter9.Chapter9LiveServerTests)
----------------------------------------------------------------------
Traceback (most recent call last):
  File "C:\Users\2251923o\AppData\Local\conda\conda\envs\rango\lib\site-packages\selenium\webdriver\common\service.py", line 76, in start
    stdin=PIPE)
  File "C:\Users\2251923o\AppData\Local\conda\conda\envs\rango\lib\subprocess.py", line 775, in __init__
    restore_signals, start_new_session)
  File "C:\Users\2251923o\AppData\Local\conda\conda\envs\rango\lib\subprocess.py", line 1178, in _execute_child
    startupinfo)
FileNotFoundError: [WinError 2] The system cannot find the file specified

During handling of the above exception, another exception occurred:

Traceback (most recent call last):
  File "H:\Workspace\tango_with_django_project2\wad2_client_side\wad2\Online\2251923\rango\tests_chapter9.py", line 47, in setUp
    self.browser = webdriver.Chrome(chrome_options=chrome_options,executable_path=r'C:\chromedriver.exe')
  File "C:\Users\2251923o\AppData\Local\conda\conda\envs\rango\lib\site-packages\selenium\webdriver\chrome\webdriver.py", line 73, in __init__
    self.service.start()
  File "C:\Users\2251923o\AppData\Local\conda\conda\envs\rango\lib\site-packages\selenium\webdriver\common\service.py", line 83, in start
    os.path.basename(self.path), self.start_error_message)
selenium.common.exceptions.WebDriverException: Message: 'chromedriver.exe' executable needs to be in PATH. Please see https://sites.google.com/a/chromium.org/chromedriver/home


----------------------------------------------------------------------
Ran 1 test in 0.516s

FAILED (errors=1)
===========================================================================


